I'm sorry, but an uncaught exception occurred.

While running game code:
  File "game/TO_LIVE_SCRIPT/ERA ONE/1937 DAY ONE/_1937_sino_japanese_war_bookmark.rpy", line 1451, in script
    Mw "It's true, I am Ma-Shih's son."
  File "game/TO_LIVE_SCRIPT/ERA ONE/1937 DAY ONE/_1937_sino_japanese_war_bookmark.rpy", line 1452, in <module>
    jump MW_CONVO_1
NameError: name 'MW_CONVO_1_taken_back' is not defined

-- Full Traceback ------------------------------------------------------------

Full traceback:
  File "game/TO_LIVE_SCRIPT/ERA ONE/1937 DAY ONE/_1937_sino_japanese_war_bookmark.rpy", line 1451, in script
    Mw "It's true, I am Ma-Shih's son."
  File "E:\renpy\renpy-6.99.12.4-sdk\renpy\ast.py", line 1628, in execute
    choice = renpy.exports.menu(choices, self.set, args, kwargs, item_arguments)
  File "E:\renpy\renpy-6.99.12.4-sdk\renpy\exports.py", line 956, in menu
    condition = renpy.python.py_eval(condition)
  File "E:\renpy\renpy-6.99.12.4-sdk\renpy\python.py", line 2059, in py_eval
    return py_eval_bytecode(code, globals, locals)
  File "E:\renpy\renpy-6.99.12.4-sdk\renpy\python.py", line 2052, in py_eval_bytecode
    return eval(bytecode, globals, locals)
  File "game/TO_LIVE_SCRIPT/ERA ONE/1937 DAY ONE/_1937_sino_japanese_war_bookmark.rpy", line 1452, in <module>
    jump MW_CONVO_1
NameError: name 'MW_CONVO_1_taken_back' is not defined

Windows-8-6.2.9200
Ren'Py 7.3.5.606
To Live 0.0.6
Sun Jun 14 16:43:44 2020
